<?xml version="1.0"?>
<robot name="hello_ros_robot">
	<link name="world"/>
	<link name="base_link">
		<visual>
			<geometry>
				<cylinder length="0.05" radius="0.1"/>
			</geometry>
			<material name="silver">
				<color rgba="0.75 0.75 0.75 1"/>
			</material>
			<origin rpy="0 0 0" xyz="0 0 0.025"/>
		</visual>
	</link>
	<joint name="fixed" type="fixed">
		<parent link="world"/>
		<child link="base_link"/>
	</joint>
	<link name="torso">
		<visual>
			<geometry>
				<cylinder length="0.5" radius="0.05"/>
			</geometry>
			<material name="silver">
				<color rgba="0.75 0.75 0.75 1"/>
			</material>
			<origin rpy="0 0 0" xyz="0 0 0.25"/>
		</visual>
	</link>
	<joint name="hip" type="continuous">
		<axis xyz="0 0 1"/>
		<parent link="base_link"/>
		<child link="torso"/>
		<origin rpy="0 0 0" xyz="0.0 0.0 0.05"/>
	</joint>
</robot>





